<mujoco model="stretch2">
  <compiler angle="radian" assetdir="stretch/assets"/>

  <option integrator="implicitfast" impratio="20" cone="elliptic">
    <flag multiccd="enable"/>
  </option>
  <size njmax="5000" nconmax="5000" />

  <default>
    <default class="stretch2">
      <geom mass="0" solref="0.005 1"/>
      <general biastype="affine"/>

      <default class="wheel2">
        <joint axis="0 0 1" damping="0.1" frictionloss="35" armature="0.1" stiffness="0.01"/>
        <velocity gear="3" kv="20" ctrlrange="-6 6"/>
      </default>

      <default class="lift2">
        <joint type="slide" axis="0 0 1" damping="35" stiffness="0.03" armature="0.01" range="0.0 1.1" frictionloss="1.5"/>
        <general ctrlrange="0.0 1.1" gainprm="400" biasprm="0 -200 -100" forcerange="-70 70"/>
      </default>

      <default class="telescope2">
        <joint type="slide" axis="0 0 1" damping="50" stiffness="0.02" armature="0.01" range="0 0.13" frictionloss="1.5"/>
        <general ctrlrange="0 0.52" gainprm="150" biasprm="0 -100 -10" forcerange="-56 56"/>
      </default>

      <default class="head2">
        <joint axis="0 0 1" damping="1"/>
        <position kp="10"/>
        <default class="head_pan2">
          <joint range="-4.04 1.73"/>
          <position ctrlrange="-4.04 1.73"/>
        </default>
        <default class="head_tilt2">
          <joint range="-1.53 0.79"/>
          <position ctrlrange="-1.53 0.79"/>
        </default>
      </default>

      <default class="wrist2">
        <joint axis="0 0 1" damping="1"/>
        <position kp="10"/>
        <default class="wrist_yaw2">
          <joint axis="0 0 -1" range="-1.39 4.42" armature="0.01" damping="7" frictionloss=".1"/>
          <position ctrlrange="-1.39 4.42" kp="20"/>
        </default>
        <default class="wrist_pitch2">
          <joint axis="0 0 1" range="-1.57 0.56" armature="0.01" frictionloss=".1"/>
          <position ctrlrange="-1.57 0.56" kp="50"/>
        </default>
        <default class="wrist_roll2">
          <joint axis="0 0 1" range="-3.14 3.14" armature="0.01" frictionloss=".1"/>
          <position ctrlrange="-3.14 3.14" kp="20"/>
        </default>
        <default class="finger_open2">
          <joint axis="0 -1 0" range="-0.6 0.6" damping="0.0001" armature="0.01" frictionloss=".1"/>
          <position ctrlrange="-0.6 0.6" kp="4000" kv="124"/>
        </default>
        <default class="finger_slide2">
          <joint type="slide" axis="0 0 1" range="-0.02 .04" armature="0.1" damping="0.0001"/>
          <position ctrlrange="-0.02 .04" kp="4000" kv="124"/>
        </default>
      </default>

      <default class="visual2">
        <geom group="2" type="mesh" contype="0" conaffinity="0"/>
      </default>
      <default class="collision2">
        <geom group="3" type="mesh"/>
        <default class="caster2">
          <geom type="sphere" size=".02" pos="-0.24 0 .02" condim="1" priority="1"/>
        </default>
        <default class="rubber2">
          <geom condim="6" friction="2 0.02 0.1" priority="1" solref="0.02 1" solimp="0.99 0.99 0.01" conaffinity="1"/>
        </default>
      </default>
    </default>
  </default>

  <!-- No <asset> block here to avoid duplication with the first Stretch -->

  <worldbody>
    <body name="r2_base_link" childclass="stretch2" pos="1.6 0.0 0.845" quat="1 0 0 0">
      <freejoint/>

      <geom mesh="base_link_0" material="Caster_Rollers_Red" density="100" class="visual2"/>
      <geom mesh="base_link_2" material="Lightbar_Green" density="100" class="visual2" shellinertia="true"/>
      <geom mesh="base_link_3" material="Power_Button_Green" density="100" class="visual2"/>
      <geom mesh="base_link_4" material="USB_Blue" density="100" class="visual2"/>
      <geom mesh="base_link_5" material="Generic_Black" density="100" class="visual2"/>
      <geom mesh="base_link_6" material="Hand_Crush_Sticker" density="100" class="visual2" shellinertia="true"/>
      <geom mesh="base_link_7" material="Pantone_705_U" density="100" class="visual2"/>
      <geom mesh="base_link_8" material="Pantone_Cool_Gray_4_U" density="100" class="visual2"/>
      <geom class="collision2" mesh="base_link_collision" mass="25.0"/>
      <geom class="caster2"/>

      <body name="r2_base_imu" pos="-0.12838 0.0031592 0.1474" euler="-3.1416 0 1.5708">
        <site name="r2_base_imu" pos="0 0 0"/>
      </body>

      <body name="r2_link_mast" pos="-0.067 0.135 0.0284" quat="1 1 0 0">
        <geom material="Generic_Black" mesh="link_mast" class="visual2"/>
        <geom mesh="link_mast" class="collision2" mass="1.8285"/>
      </body>

      <body name="r2_link_head" pos="-0.067 0.134995 1.3584" quat="-1 0 0 1">
        <geom mesh="link_head_0" material="Runstop_White_Glow" class="visual2"/>
        <geom mesh="link_head_1" material="Generic_Black" class="visual2"/>
        <geom mesh="link_head_2" material="Speaker_Housing_Black" class="visual2"/>
        <geom mesh="link_head_3" material="Reflective_Metal" class="visual2"/>
        <geom mesh="link_head_4" material="Reflective_Metal" class="visual2"/>
        <geom mesh="link_head_5" material="Pure_Black" class="visual2"/>
        <geom mesh="link_head_6" material="Reflective_Metal" class="visual2"/>
        <geom mesh="link_head_7" material="Plug_White" class="visual2"/>
        <geom mesh="link_head_8" material="3D_Print_Black" class="visual2"/>
        <geom mesh="link_head_9" material="Respeaker_Blue_Glow" class="visual2"/>
        <geom mesh="link_head_10" material="Pantone_Black_6_U" class="visual2"/>
        <geom mesh="link_head_11" material="Generic_Black" class="visual2"/>
        <geom mesh="link_head_10" class="collision2" mass="0.833027236718691"/>
      </body>

      <body name="r2_link_aruco_right_base" pos="-0.0015028 -0.130497 0.159748" quat="1 0 0 -1">
        <geom material="Aruco_Right_Base_Sticker" mesh="link_aruco_right_base" class="visual2" mass="3.6E-06" shellinertia="true"/>
        <geom mesh="link_aruco_right_base" class="collision2"/>
      </body>
      <body name="r2_link_aruco_left_base" pos="-0.0015028 0.130497 0.159748" quat="1 0 0 -1">
        <geom material="Aruco_Left_Base_Sticker" mesh="link_aruco_left_base" class="visual2" mass="3.6E-06" shellinertia="true"/>
        <geom mesh="link_aruco_left_base" class="collision2"/>
      </body>

      <body name="r2_laser" pos="0.004 0 0.1664" quat="0 0 0 1">
        <geom material="Laser_Black" mesh="laser" class="visual2" mass="0.24"/>
        <geom mesh="laser" class="collision2"/>
        <replicate count="360" euler="0 0 0.0174533">
          <site name="r2_lidar" zaxis="1 0 0"/>
        </replicate>
      </body>

      <body name="r2_link_right_wheel" pos="0 -0.17035 0.0508" quat="1 -1 0 0">
        <joint name="r2_joint_right_wheel" class="wheel2"/>
        <geom mesh="link_right_wheel_0" material="Wheel_Rubber_Gray" class="visual2" mass="0.15"/>
        <geom mesh="link_right_wheel_1" material="Generic_Black" class="visual2"/>
        <geom class="collision2" type="cylinder" size=".05 .0125" pos="0 0 0.0125" condim="6"/>
      </body>

      <body name="r2_link_left_wheel" pos="0 0.17035 0.0508" quat="1 -1 0 0">
        <joint name="r2_joint_left_wheel" class="wheel2"/>
        <geom mesh="link_left_wheel_0" material="Wheel_Rubber_Gray" class="visual2" mass="0.15"/>
        <geom mesh="link_left_wheel_1" material="Generic_Black" class="visual2"/>
        <geom class="collision2" type="cylinder" size=".05 .0125" pos="0 0 -0.0125" condim="6"/>
      </body>

      <body name="r2_link_lift" gravcomp="1" pos="-0.104385 0.134999 0.2" quat="1 0 0 1">
        <joint name="r2_joint_lift" class="lift2"/>
        <geom mesh="link_lift_0" material="Pantone_705_U" class="visual2"/>
        <geom mesh="link_lift_2" material="Pure_Black" class="visual2"/>
        <geom mesh="link_lift_3" material="Reflective_Metal" class="visual2"/>
        <geom mesh="link_lift_4" material="Plug_White" class="visual2"/>
        <geom mesh="link_lift_5" material="Pantone_Black_6_U" class="visual2"/>
        <geom mesh="link_lift_6" material="Generic_Black" class="visual2"/>
        <geom mesh="link_lift_7" material="Generic_Black" class="visual2"/>
        <geom mesh="link_lift_8" material="3D_Print_Black" class="visual2"/>
        <geom mesh="link_lift_9" material="Pantone_Black_6_U" class="visual2"/>
        <geom mesh="link_lift_0" class="collision2"/>
        <geom mesh="link_lift_2" class="collision2"/>
        <geom mesh="link_lift_3" class="collision2"/>
        <geom mesh="link_lift_4" class="collision2"/>
        <geom mesh="link_lift_5" class="collision2"/>
        <geom mesh="link_lift_6" class="collision2"/>
        <geom mesh="link_lift_7" class="collision2"/>
        <geom mesh="link_lift_8" class="collision2" mass="1.5"/>
        <geom mesh="link_lift_9" class="collision2" mass="1.5"/>

        <body name="r2_link_arm_l4" gravcomp="1">
          <geom mesh="link_arm_l4_0" pos="-0.2547 0 0" quat="0.5 0.5 -0.5 -0.5" material="Carbon_Fiber" class="visual2"/>
          <geom mesh="link_arm_l4_1" pos="-0.2547 0 0" quat="0.5 0.5 -0.5 -0.5" material="3D_Print_Black" class="visual2"/>
          <geom mesh="link_arm_l4_0" pos="-0.2547 0 0" quat="0.5 0.5 -0.5 -0.5" class="collision2" mass="0.168095"/>
          <geom mesh="link_arm_l4_1" pos="-0.2547 0 0" quat="0.5 0.5 -0.5 -0.5" class="collision2"/>

          <body name="r2_link_arm_l3" pos="-0.2677 0 0" quat="0.5 0.5 -0.5 -0.5" gravcomp="1">
            <joint name="r2_joint_arm_l3" class="telescope2"/>
            <geom mesh="link_arm_l3_0" material="Carbon_Fiber" class="visual2" mass="0.162893"/>
            <geom mesh="link_arm_l3_1" material="3D_Print_Black" class="visual2"/>
            <geom mesh="link_arm_l3_0" class="collision2"/>
            <geom mesh="link_arm_l3_1" class="collision2"/>

            <body name="r2_link_arm_l2" pos="0 0 0.013" gravcomp="1">
              <joint name="r2_joint_arm_l2" class="telescope2"/>
              <geom mesh="link_arm_l2_0" material="Carbon_Fiber" class="visual2" mass="0.157139"/>
              <geom mesh="link_arm_l2_1" material="3D_Print_Black" class="visual2"/>
              <geom mesh="link_arm_l2_0" class="collision2"/>
              <geom mesh="link_arm_l2_1" class="collision2"/>

              <body name="r2_link_arm_l1" pos="0 0 0.013" gravcomp="1">
                <joint name="r2_joint_arm_l1" class="telescope2"/>
                <geom mesh="link_arm_l1_0" material="Carbon_Fiber" class="visual2" mass="0.151382"/>
                <geom mesh="link_arm_l1_1" material="3D_Print_Black" class="visual2"/>
                <geom mesh="link_arm_l1_0" class="collision2"/>
                <geom mesh="link_arm_l1_1" class="collision2"/>

                <body name="r2_link_arm_l0" pos="0 0 -0.01375" quat="1 0 0 0" gravcomp="1">
                  <joint name="r2_joint_arm_l0" class="telescope2"/>
                  <geom mesh="link_arm_l0_0" material="3D_Print_Black" class="visual2"/>
                  <geom mesh="link_arm_l0_1" material="Carbon_Fiber" class="visual2" mass="0.28501"/>
                  <geom mesh="link_arm_l0_2" material="Generic_Black" class="visual2"/>
                  <geom mesh="link_arm_l0_0" class="collision2"/>
                  <geom mesh="link_arm_l0_1" class="collision2"/>
                  <geom mesh="link_arm_l0_2" class="collision2"/>

                  <body name="r2_link_aruco_top_wrist" pos="0.04725 0.029285 0" quat="0 0 1 1">
                    <geom material="Aruco_Top_Wrist_Sticker" mesh="link_aruco_top_wrist" class="visual2" mass="3.6E-06" shellinertia="true"/>
                    <geom mesh="link_aruco_top_wrist" class="collision2"/>
                  </body>

                  <body name="r2_link_aruco_inner_wrist" pos="0.04725 -0.0119 -0.02725" quat="0 0 1 0">
                    <geom material="Aruco_Inner_Wrist_Sticker" mesh="link_aruco_inner_wrist" class="visual2" mass="3.6E-06" shellinertia="true"/>
                    <geom mesh="link_aruco_inner_wrist" class="collision2"/>
                  </body>

                  <!-- Dex Wrist 3 -->
                  <body name="r2_link_wrist_yaw" pos="0.083 -0.03075 0" quat="-1 -1 0 0" gravcomp="1">
                    <joint name="r2_joint_wrist_yaw" class="wrist_yaw2"/>
                    <geom material="Generic_Black" mesh="link_wrist_yaw" mass="0.1445" class="visual2"/>
                    <geom mesh="link_wrist_yaw" class="collision2"/>
                    <geom quat="0 1 1 0" pos="0 0 0" mesh="link_DW3_wrist_yaw_bottom" material="Generic_Black" class="visual2"/>
                    <geom mesh="link_DW3_wrist_yaw_bottom" class="collision2"/>

                    <body name="r2_link_DW3_wrist_pitch" pos="-0.01946 0 0.0305" euler="0 1.57 -1.57" gravcomp="1">
                      <joint name="r2_joint_wrist_pitch" axis="0 0 -1" class="wrist_pitch2"/>
                      <geom material="Generic_Black" mesh="link_DW3_wrist_pitch" mass="0.1165" class="visual2"/>
                      <geom mesh="link_DW3_wrist_pitch" class="collision2"/>
                      <geom pos="-0.0265 -0.024 0.0196" quat="1 0 0 1" mesh="link_DW3_wrist_quick_connect" material="Generic_Black" class="visual2"/>
                      <geom mesh="link_DW3_wrist_quick_connect" class="collision2"/>

                      <body name="r2_link_SG3_gripper_body" pos="-0.0399 -0.024 0.0196" quat="1 0 -1 0" gravcomp="1">
                        <joint name="r2_joint_wrist_roll" class="wrist_roll2"/>
                        <geom material="Generic_Black" mesh="link_SG3_gripper_body" mass="0.29" class="visual2"/>
                        <geom mesh="link_SG3_gripper_body" class="collision2"/>

                        <body name="r2_link_SG3_aruco_d405" pos="0 0.0671264013906604 0.0297716109784749" euler="-1.397059993 3.139694278 -0.001741181" gravcomp="1">
                          <geom material="Aruco_gripper_cam_Sticker" mesh="link_SG3_aruco_d405" class="visual2" mass="3.6E-06" shellinertia="true"/>
                          <geom mesh="link_SG3_aruco_d405" class="collision2"/>

                          <body name="r2_link_d405" pos="0 -0.03068 0" euler="1.57 0 0">
                            <geom material="Reflective_Metal" mesh="link_d405" mass="0.29" class="visual2"/>
                            <geom material="Gray_Lens" mesh="link_d405_lens" pos="0 0 0" euler="0 0 0" mass="3.6E-06" class="visual2"/>
                            <geom material="Pantone_Black_6_U" mesh="link_d405_front_plate" pos="0 0 0" euler="0 0 0" mass="3.6E-06" class="visual2"/>
                            <geom mesh="link_d405" class="collision2"/>

                            <body name="r2_d405_cam" pos="0 0 0" euler="0 0 3.14">
                              <camera name="r2_d405_rgb" pos="0 0 0" euler="-3.14 0 -3.14"/>
                              <camera name="r2_d405_depth" pos="0 0 0" euler="-3.14 0 -3.14"/>
                            </body>
                          </body>
                        </body>

                        <body name="r2_link_grasp_center" pos="0 0 0.23" euler="-1.5707963267949 -1.5707963267948 0"/>

                        <!-- Gripper -->
                        <body name="r2_link_gripper_slider" euler="0 0 0" pos="0 0 0" gravcomp="1">
                          <joint name="r2_joint_gripper_slide" class="finger_slide2"/>
                          <geom type="box" size=".03 .005 .005" mass=".05" class="visual2" rgba="0 0 0 0"/>

                          <body name="r2_link_gripper_finger_left" pos="0.02292 0.0020217 0.035297" euler="0 -1.57 3.1416" gravcomp="1">
                            <joint name="r2_joint_gripper_finger_left_open" class="finger_open2" stiffness="1"/>
                            <geom mesh="link_SG3_gripper_left_finger_0" euler="1.57 0 0" material="Generic_Black" mass="0.05" class="visual2"/>
                            <geom mesh="link_SG3_gripper_left_finger_0" euler="1.57 0 0" class="collision2"/>
                            <geom mesh="link_SG3_gripper_left_finger_1" euler="1.57 0 0" material="White_Plastic" class="visual2"/>
                            <geom mesh="link_SG3_gripper_left_finger_1" euler="1.57 0 0" class="collision2"/>
                            <geom mesh="link_SG3_gripper_inner_finger" pos="-0.17777 0.0018452 -0.011272" euler="3.1416 0.28 0" material="Reflective_Metal" mass="0.05" class="visual2"/>

                            <body name="r2_rubber_tip_left" pos="-0.17777 0.0018452 -0.011272" euler="0 -0.2618 -0.010379">
                              <joint name="r2_rubber_left_x" type="hinge" axis="1 0 0" damping=".01" stiffness="1" springref="0"/>
                              <joint name="r2_rubber_left_y" type="hinge" axis="0 1 0" damping=".01" stiffness="1" springref="0"/>
                              <geom class="visual2" mesh="link_SG3_gripper_left_fingertip" mass="0.005" material="suction_rubber"/>
                              <geom type="box" size="0.02 0.02 0.01" pos="0 0 0.01" class="rubber2"/>
                            </body>

                            <body name="r2_link_SG3_gripper_left_finger_aruco" pos="-0.14425 0.0014877 -0.005189" euler="0.19199 0.95993 3.1312">
                              <geom material="Aruco_left_finger_Sticker" mesh="link_SG3_gripper_left_finger_aruco" class="visual2" mass="3.6E-06" shellinertia="true"/>
                              <geom mesh="link_SG3_gripper_left_finger_aruco" class="collision2"/>
                            </body>
                          </body>

                          <body name="r2_link_gripper_finger_right" pos="-0.023281 0 0.035287" euler="-3.1416 -1.57 3.1416" gravcomp="1">
                            <joint name="r2_joint_gripper_finger_right_open" class="finger_open2" stiffness="1"/>
                            <geom mesh="link_SG3_gripper_right_finger_0" euler="1.57 0 0" material="Generic_Black" mass="0.05" class="visual2"/>
                            <geom mesh="link_SG3_gripper_right_finger_0" euler="1.57 0 0" class="collision2"/>
                            <geom mesh="link_SG3_gripper_right_finger_1" euler="1.57 0 0" material="White_Plastic" class="visual2"/>
                            <geom mesh="link_SG3_gripper_right_finger_1" euler="1.57 0 0" class="collision2"/>
                            <geom mesh="link_SG3_gripper_inner_finger" pos="0.17778 0 0.011272" euler="3.1416 -2.8616 0" material="Reflective_Metal" mass="0.05" class="visual2"/>

                            <body name="r2_rubber_tip_right" pos="0.17778 0 0.011272" euler="-3.1416 0.2618 -3.1416" gravcomp="1">
                              <joint name="r2_rubber_right_x" type="hinge" axis="1 0 0" damping=".01" stiffness="1" springref="0"/>
                              <joint name="r2_rubber_right_y" type="hinge" axis="0 1 0" damping=".01" stiffness="1" springref="0"/>
                              <geom class="visual2" material="suction_rubber" mesh="link_SG3_gripper_right_fingertip" mass="0.005"/>
                              <geom type="box" size="0.02 0.02 0.01" pos="0 0 0.01" class="rubber2"/>
                            </body>

                            <body name="r2_link_SG3_gripper_right_finger_aruco" pos="0.14426 0 0.005189" euler="-2.9496 -0.95993 3.1416">
                              <geom material="Aruco_right_finger_Sticker" mesh="link_SG3_gripper_right_finger_aruco" class="visual2" mass="3.6E-06" shellinertia="true"/>
                              <geom mesh="link_SG3_gripper_right_finger_aruco" class="collision2"/>
                            </body>
                          </body>
                        </body>
                      </body>
                    </body>
                  </body>
                </body>
              </body>
            </body>
          </body>
        </body>

        <body name="r2_link_aruco_shoulder" pos="-0.0133769 0.0558541 0.0865" quat="1 0 0 0">
          <geom material="Aruco_Shoulder_Sticker" mesh="link_aruco_shoulder" class="visual2" mass="3.6E-06" shellinertia="true"/>
          <geom mesh="link_aruco_shoulder" class="collision2"/>
        </body>
      </body>

      <body name="r2_link_head_pan" pos="0.00610002 0 1.3552" quat="-1 0 0 0">
        <joint name="r2_joint_head_pan" class="head_pan2"/>
        <geom mesh="link_head_pan_0" material="3D_Print_Black" class="visual2"/>
        <geom mesh="link_head_pan_1" material="Generic_Black" class="visual2" mass="0.127376"/>
        <geom mesh="link_head_pan_0" class="collision2"/>
        <geom mesh="link_head_pan_1" class="collision2"/>

        <body name="r2_link_head_tilt" pos="-0.0013 0.0277625 -0.0533108" quat="1 1 0 0">
          <joint name="r2_joint_head_tilt" class="head_tilt2"/>
          <geom mesh="link_head_tilt_0" material="Pantone_Cool_Gray_4_U" class="visual2" mass="0.1311085"/>
          <geom mesh="link_head_tilt_1" material="3D_Print_Black" class="visual2" mass="0.1311085"/>
          <geom mesh="link_head_tilt_0" class="collision2"/>
          <geom mesh="link_head_tilt_1" class="collision2"/>

          <body name="r2_realsense" pos="0.0406 0.0053 0.0307" euler="0 0 0">
            <camera name="r2_d435i_camera_rgb" pos="0 0.015 0" euler="1.57 -1.57 0"/>
            <camera name="r2_d435i_camera_depth" euler="1.57 -1.57 0"/>
          </body>

          <body name="r2_link_SE3_head_nav_cam" pos="0.04 -0.0412 -0.0246" euler="0 1.5707963 0">
            <joint name="r2_joint_head_nav_cam" class="head_tilt2" stiffness="10"/>
            <geom mesh="link_SE3_head_nav_cam" material="Generic_Black" class="visual2" mass="0.028346169831483"/>
            <body name="r2_head_nav_cam" pos="0 0 0">
              <camera name="r2_nav_camera_rgb" pos="0 0 0" euler="-3.1415926 0 -1.5707963"/>
            </body>
          </body>
        </body>
      </body>
    </body>
  </worldbody>

  <contact>
    <exclude body1="r2_link_head_pan" body2="r2_link_head"/>
    <exclude body1="r2_link_left_wheel" body2="r2_base_link"/>
    <exclude body1="r2_link_right_wheel" body2="r2_base_link"/>
    <exclude body1="r2_link_lift" body2="r2_link_mast"/>
    <exclude body1="r2_link_lift" body2="r2_link_head"/>
    <exclude body1="r2_link_arm_l0" body2="r2_link_arm_l4"/>
    <exclude body1="r2_link_arm_l0" body2="r2_link_arm_l1"/>
    <exclude body1="r2_link_arm_l1" body2="r2_link_arm_l4"/>
    <exclude body1="r2_link_arm_l2" body2="r2_link_arm_l4"/>
    <exclude body1="r2_link_arm_l3" body2="r2_link_arm_l4"/>
    <exclude body1="r2_link_arm_l0" body2="r2_link_arm_l2"/>
    <exclude body1="r2_link_arm_l0" body2="r2_link_arm_l3"/>
    <exclude body1="r2_link_arm_l0" body2="r2_link_lift"/>
    <exclude body1="r2_link_arm_l1" body2="r2_link_arm_l3"/>
    <exclude body1="r2_link_arm_l1" body2="r2_link_lift"/>
    <exclude body1="r2_link_arm_l2" body2="r2_link_lift"/>
    <exclude body1="r2_link_wrist_yaw" body2="r2_link_arm_l0"/>
    <exclude body1="r2_link_wrist_yaw" body2="r2_link_arm_l1"/>
    <exclude body1="r2_link_wrist_yaw" body2="r2_link_arm_l2"/>
    <exclude body1="r2_link_wrist_yaw" body2="r2_link_arm_l3"/>
    <exclude body1="r2_link_wrist_yaw" body2="r2_link_arm_l4"/>
    <exclude body1="r2_link_gripper_finger_left" body2="r2_link_DW3_wrist_pitch"/>
    <exclude body1="r2_link_gripper_finger_right" body2="r2_link_DW3_wrist_pitch"/>
    <exclude body1="r2_link_gripper_finger_left" body2="r2_link_wrist_yaw"/>
    <exclude body1="r2_link_gripper_finger_right" body2="r2_link_wrist_yaw"/>
    <exclude body1="r2_link_gripper_finger_left" body2="r2_link_SG3_gripper_body"/>
    <exclude body1="r2_link_gripper_finger_right" body2="r2_link_SG3_gripper_body"/>
    <exclude body1="r2_rubber_tip_right" body2="r2_rubber_tip_left"/>
  </contact>

  <tendon>
    <fixed name="r2_extend">
      <joint joint="r2_joint_arm_l0" coef="1"/>
      <joint joint="r2_joint_arm_l1" coef="1"/>
      <joint joint="r2_joint_arm_l2" coef="1"/>
      <joint joint="r2_joint_arm_l3" coef="1"/>
    </fixed>
  </tendon>

  <equality>
    <joint joint1="r2_joint_arm_l0" joint2="r2_joint_arm_l1"/>
    <joint joint1="r2_joint_arm_l1" joint2="r2_joint_arm_l2"/>
    <joint joint1="r2_joint_arm_l2" joint2="r2_joint_arm_l3"/>
    <joint joint1="r2_joint_gripper_finger_left_open" joint2="r2_joint_gripper_slide" polycoef="0 10 0 0 0" solref="0.005 1"/>
    <joint joint1="r2_joint_gripper_finger_right_open" joint2="r2_joint_gripper_slide" polycoef="0 10 0 0 0" solref="0.005 1"/>
  </equality>

  <actuator>
    <velocity name="r2_left_wheel_vel" joint="r2_joint_left_wheel" class="wheel2"/>
    <velocity name="r2_right_wheel_vel" joint="r2_joint_right_wheel" class="wheel2"/>
    <position name="r2_lift" joint="r2_joint_lift" class="lift2"/>
    <position name="r2_arm" tendon="r2_extend" class="telescope2"/>
    <position name="r2_wrist_yaw" joint="r2_joint_wrist_yaw" class="wrist_yaw2"/>
    <position name="r2_wrist_pitch" joint="r2_joint_wrist_pitch" class="wrist_pitch2"/>
    <position name="r2_wrist_roll" joint="r2_joint_wrist_roll" class="wrist_roll2"/>
    <position name="r2_gripper" joint="r2_joint_gripper_slide" class="finger_slide2"/>
    <position name="r2_head_pan" joint="r2_joint_head_pan" class="head_pan2"/>
    <position name="r2_head_tilt" joint="r2_joint_head_tilt" class="head_tilt2"/>
  </actuator>

  <sensor>
    <gyro name="r2_base_gyro" site="r2_base_imu"/>
    <accelerometer name="r2_base_accel" site="r2_base_imu"/>
    <rangefinder name="r2_base_lidar" site="r2_lidar" cutoff="10.0"/>
  </sensor>

  <keyframe>
    <key name="r2_home" ctrl="0 0 0.6 0.1 0 0 0 0 0 0"/>
    <key name="r2_stow" ctrl="0 0 0.23 0 3.14 -0.4 0 0 0 0"/>
  </keyframe>
</mujoco>
